- en: 例外処理
  prefs:
  - PREF_H1
  type: TYPE_NORMAL
- en: 原文：[https://jsprimer.net/basic/error-try-catch/](https://jsprimer.net/basic/error-try-catch/)
  prefs:
  - PREF_BQ
  type: TYPE_NORMAL
- en: この章ではJavaScriptにおける例外処理について学びます。
  prefs: []
  type: TYPE_NORMAL
- en: '[](#try-catch)*try...catch構文*'
  prefs:
  - PREF_H2
  type: TYPE_NORMAL
- en: '*[try...catch](https://developer.mozilla.org/ja/docs/Web/JavaScript/Reference/Statements/try...catch)構文は例外が発生しうるブロックをマークし、例外が発生したときの処理を記述するための構文です。'
  prefs: []
  type: TYPE_NORMAL
- en: try...catch構文の`try`ブロック内で例外が発生すると、`try`ブロック内のそれ以降の処理は実行されず、`catch`節に処理が移行します。
    `catch`節は、`try`ブロック内で例外が発生すると、発生したエラーオブジェクトとともに呼び出されます。 `finally`節は、`try`ブロック内で例外が発生したかどうかには関係なく、必ず`try`文の最後に実行されます。
  prefs: []
  type: TYPE_NORMAL
- en: 次のコードでは、`try`ブロックで例外が発生し、`catch`節の処理が実行され、最後に`finally`節の処理が実行されます。
  prefs: []
  type: TYPE_NORMAL
- en: '[PRE0]'
  prefs: []
  type: TYPE_PRE
- en: また、`catch`節と`finally`節のうち、片方が存在していれば、もう片方の節は省略できます。 `finally`節のみを書いた場合は例外がキャッチされないため、`finally`節を実行後に例外が発生します。
  prefs: []
  type: TYPE_NORMAL
- en: '[PRE1]'
  prefs: []
  type: TYPE_PRE
- en: '[](#throw)*throw文*'
  prefs:
  - PREF_H2
  type: TYPE_NORMAL
- en: '*[throw](https://developer.mozilla.org/ja/docs/Web/JavaScript/Reference/Statements/throw)文を使うとユーザーが例外を投げることができます。
    例外として投げられたオブジェクトは、`catch`節で関数の引数のようにアクセスできます。 `catch`節でオブジェクトを参照できる識別子を[例外識別子](https://developer.mozilla.org/ja/docs/Web/JavaScript/Reference/Statements/try...catch#The_exception_identifier)と呼びます。'
  prefs: []
  type: TYPE_NORMAL
- en: 次のコードでは、`catch`節の`error`識別子でキャッチしたエラーオブジェクトを参照しています。
  prefs: []
  type: TYPE_NORMAL
- en: '[PRE2]'
  prefs: []
  type: TYPE_PRE
- en: '[](#error-object)*エラーオブジェクト*'
  prefs:
  - PREF_H2
  type: TYPE_NORMAL
- en: '*`throw`文ではエラーオブジェクトを例外として投げることができます。 ここでは、`throw`文で例外として投げられるエラーオブジェクトについて見ていきます。'
  prefs: []
  type: TYPE_NORMAL
- en: '[](#error)*Error*'
  prefs:
  - PREF_H3
  type: TYPE_NORMAL
- en: '*`Error`オブジェクトのインスタンスは`new Error("エラーメッセージ")`で作成します。 コンストラクタの第一引数には、エラーメッセージとなる文字列を渡します。
    渡したエラーメッセージはErrorの`message`プロパティで参照できます。'
  prefs: []
  type: TYPE_NORMAL
- en: 次のコードでは、`assertPositiveNumber`関数でエラーオブジェクトを作成し、例外として`throw`しています。 投げられたオブジェクトはcatch節の例外識別子（`error`）から取得でき、エラーメッセージが確認できます。
  prefs: []
  type: TYPE_NORMAL
- en: '[PRE3]'
  prefs: []
  type: TYPE_PRE
- en: '`throw`文はあらゆるオブジェクトを例外として投げられますが、基本的に`Error`オブジェクトのインスタンスを投げることを推奨します。 その理由は後述する**スタックトレース**のためです。
    `Error`オブジェクトはインスタンスの作成時に、そのインスタンスが作成されたファイル名や行数などのデバッグに役立つ情報を持っています。 文字列のような`Error`オブジェクトではないオブジェクトを投げてしまうと、スタックトレースが得られません。'
  prefs: []
  type: TYPE_NORMAL
- en: そのため、次のように`throw`文で`Error`オブジェクトではないものを投げるのは非推奨です。
  prefs: []
  type: TYPE_NORMAL
- en: '[PRE4]'
  prefs: []
  type: TYPE_PRE
- en: '[](#built-in-error)*ビルトインエラー*'
  prefs:
  - PREF_H3
  type: TYPE_NORMAL
- en: '*エラーには状況に合わせたいくつかの種類があり、これらはビルトインエラーとして定義されています。 ビルトインエラーとは、ECMAScript仕様や実行環境に組み込みで定義されているエラーオブジェクトです。
    ビルトインエラーとして投げられるエラーオブジェクトは、すべて`Error`オブジェクトを継承したオブジェクトのインスタンスです。 そのため、ユーザーが定義したエラーと同じように例外処理できます。'
  prefs: []
  type: TYPE_NORMAL
- en: ビルトインエラーにはいくつか種類がありますが、ここでは代表的なものを紹介します。
  prefs: []
  type: TYPE_NORMAL
- en: '[](#reference-error)*ReferenceError*'
  prefs:
  - PREF_H4
  type: TYPE_NORMAL
- en: '*[ReferenceError](https://developer.mozilla.org/ja/docs/Web/JavaScript/Reference/Global_Objects/ReferenceError)は存在しない変数や関数などの識別子が参照された場合のエラーです。
    次のコードでは、存在しない変数を参照しているため`ReferenceError`例外が投げられます。'
  prefs: []
  type: TYPE_NORMAL
- en: '[PRE5]'
  prefs: []
  type: TYPE_PRE
- en: '[](#syntax-error)*SyntaxError*'
  prefs:
  - PREF_H4
  type: TYPE_NORMAL
- en: '*[SyntaxError](https://developer.mozilla.org/ja/docs/Web/JavaScript/Reference/Global_Objects/SyntaxError)は構文的に不正なコードを解釈しようとした場合のエラーです。
    基本的に`SyntaxError`例外は、JavaScriptを実行する前のパース段階で発生します。 そのため、実行前に発生する例外である`SyntaxError`は、実行時のエラーをキャッチする`try...catch`文ではcatchできません。'
  prefs: []
  type: TYPE_NORMAL
- en: '[PRE6]'
  prefs: []
  type: TYPE_PRE
- en: 次のコードでは、`eval`関数を使って実行時に`SyntaxError`を無理やり発生させ、構文エラーが`SyntaxError`であることを確認しています。
    `eval`関数は渡した文字列をJavaScriptとして実行する関数です。 実行時に発生した`SyntaxError`は、`try...catch`文でもcatchできます。
  prefs: []
  type: TYPE_NORMAL
- en: '[PRE7]'
  prefs: []
  type: TYPE_PRE
- en: '[](#type-error)*TypeError*'
  prefs:
  - PREF_H4
  type: TYPE_NORMAL
- en: '*[TypeError](https://developer.mozilla.org/ja/docs/Web/JavaScript/Reference/Global_Objects/TypeError)は値が期待される型ではない場合のエラーです。
    次のコードでは、関数ではないオブジェクトを関数呼び出ししているため、`TypeError`例外が投げられます。'
  prefs: []
  type: TYPE_NORMAL
- en: '[PRE8]'
  prefs: []
  type: TYPE_PRE
- en: '[](#throw-built-in-error)*ビルトインエラーを投げる*'
  prefs:
  - PREF_H3
  type: TYPE_NORMAL
- en: '*ビルトインエラーのインスタンスを作成し、そのインスタンスを例外として投げることもできます。 通常の`Error`オブジェクトと同じように、それぞれのビルトインエラーオブジェクトを`new`してインスタンスを作成できます。'
  prefs: []
  type: TYPE_NORMAL
- en: たとえば関数の引数を文字列に限定したい場合は、次のように`TypeError`例外を投げるとよいでしょう。 メッセージを確認しなくても、エラーの名前だけで型に関する例外だとすぐにわかります。
  prefs: []
  type: TYPE_NORMAL
- en: '[PRE9]'
  prefs: []
  type: TYPE_PRE
- en: '[](#error-and-debug)*エラーとデバッグ*'
  prefs:
  - PREF_H2
  type: TYPE_NORMAL
- en: '*JavaScript開発においてデバッグ中に発生したエラーを理解することは非常に重要です。 エラーが持つ情報を活用することで、ソースコードのどこでどのような例外が投げられたのかを知ることができます。'
  prefs: []
  type: TYPE_NORMAL
- en: エラーはすべて`Error`オブジェクトを拡張したオブジェクトで宣言されています。 つまり、エラーの名前を表す`name`プロパティと内容を表す`message`プロパティを持っています。
    この2つのプロパティを確認することで、多くの場面で開発の助けとなるでしょう。
  prefs: []
  type: TYPE_NORMAL
- en: 次のコードでは、`try...catch`文で囲っていない部分で例外が発生しています。
  prefs: []
  type: TYPE_NORMAL
- en: '[PRE10]'
  prefs: []
  type: TYPE_PRE
- en: このスクリプトを読み込むと、投げられた例外についてのログがコンソールに出力されます。 ここではFirefoxにおける実行例を示します。
  prefs: []
  type: TYPE_NORMAL
- en: '![コンソールでのエラー表示（Firefox）](../Images/fa3c3b721816f38fb58865327e9ee6c3.png)'
  prefs: []
  type: TYPE_IMG
- en: このエラーログには次の情報が含まれています。
  prefs: []
  type: TYPE_NORMAL
- en: '| メッセージ | 意味 |'
  prefs: []
  type: TYPE_TB
- en: '| --- | --- |'
  prefs: []
  type: TYPE_TB
- en: '| `ReferenceError: x is not defined` | エラーの種類は`ReferenceError`で、`x`が未定義であること。
    |'
  prefs: []
  type: TYPE_TB
- en: '| `error.js:3:5` | 例外が`error.js`の3行目5列目で発生したこと。つまり`x++;`であること。 |'
  prefs: []
  type: TYPE_TB
- en: また、メッセージの後には例外のスタックトレースが表示されています。 スタックトレースとは、プログラムの実行過程を記録した内容で、どの処理によってエラーが発生したかが書かれています。
  prefs: []
  type: TYPE_NORMAL
- en: スタックトレースの最初の行が実際に例外が発生した場所です。つまり、3行目の `x++;` で例外が発生しています
  prefs:
  - PREF_UL
  type: TYPE_NORMAL
- en: 次の行には、そのコードの呼び出し元が記録されています。つまり、3行目のコードを実行したのは5行目の`fn`関数の呼び出しです
  prefs:
  - PREF_UL
  type: TYPE_NORMAL
- en: このように、スタックトレースは上から下へ呼び出し元をたどれるように記録されています。
  prefs: []
  type: TYPE_NORMAL
- en: コンソールに表示されるエラーログには多くの情報が含まれています。 MDNの[JavaScriptエラーリファレンス](https://developer.mozilla.org/ja/docs/Web/JavaScript/Reference/Errors)には、ブラウザが投げるビルトインエラーの種類とメッセージが網羅されています。
    開発中にビルトインエラーが発生したときには、リファレンスを見て解決方法を探すとよいでしょう。
  prefs: []
  type: TYPE_NORMAL
- en: '[](#console.error)*`console.error`とスタックトレース*'
  prefs:
  - PREF_H2
  type: TYPE_NORMAL
- en: '*`console.error`メソッドではメッセージと合わせてスタックトレースをコンソールへ出力できます。'
  prefs: []
  type: TYPE_NORMAL
- en: 次のコードを実行して、`console.log`と`console.error`の出力結果を見比べてみます。
  prefs: []
  type: TYPE_NORMAL
- en: '[PRE11]'
  prefs: []
  type: TYPE_PRE
- en: このコードをFirefoxで実行するとコンソール出力は次の図のようになります。
  prefs: []
  type: TYPE_NORMAL
- en: '![console.logとconsole.errorの出力結果](../Images/0acbabe37f577404122b0b87f7220370.png)'
  prefs: []
  type: TYPE_IMG
- en: '`console.log`はメッセージだけなのに対して、`console.error`ではメッセージと共にスタックトレースが出力されます。 そのため、エラーが発生した場合のコンソールへのメッセージ出力に`console.error`を利用することでデバッグがしやすくなります。'
  prefs: []
  type: TYPE_NORMAL
- en: また、ほとんどのブラウザには`console.log`や`console.error`の出力をフィルタリングできる機能が備わっています。 ただのログ出力には`console.log`を使い、エラーに関するログ出力には`console.error`を使うことで、ログの重要度が区別しやすくなります。
  prefs: []
  type: TYPE_NORMAL
- en: '[](#error-cause)*[ES2022] Error Cause*'
  prefs:
  - PREF_H2
  type: TYPE_NORMAL
- en: '*エラーをキャッチした際、新しいメッセージを持たせた別のエラーを再度投げ直すことで、デバッグに役立つ情報を付与できます。 これを実現する時に、新しくErrorオブジェクトを作成してthrowすることで実現できます。
    しかし、この方法には本来のエラーのスタックトレースが失われるという問題があります。'
  prefs: []
  type: TYPE_NORMAL
- en: '[PRE12]'
  prefs: []
  type: TYPE_PRE
- en: このスタックトレースが失われる問題を解決するには、ES2022で追加されたErrorの`cause`オプションが利用できます。 新しいエラーオブジェクトを作成する際に、第2引数の`cause`オプションに本来のエラーオブジェクトを渡すことで、本来のスタックトレースを保持できます。
  prefs: []
  type: TYPE_NORMAL
- en: '[PRE13]'
  prefs: []
  type: TYPE_PRE
- en: このスクリプトを読み込むと、`sumNumsStrings` の例外に `safeParseInt` から投げられたスタックトレースが付与された状態のエラーログがコンソールに出力されます。
    ここではFirefoxにおける実行例を示します。
  prefs: []
  type: TYPE_NORMAL
- en: '![safeParseIntのスタックトレースが含まれたconsole.errorの出力結果](../Images/82ca3eb6268226652f98a961bfcdbfb8.png)'
  prefs: []
  type: TYPE_IMG
- en: '[](#conclusion)*まとめ*'
  prefs:
  - PREF_H2
  type: TYPE_NORMAL
- en: '*この章では、例外処理とエラーオブジェクトについて学びました。'
  prefs: []
  type: TYPE_NORMAL
- en: '`try...catch`構文は`try`ブロック内で発生した例外を処理できる'
  prefs:
  - PREF_UL
  type: TYPE_NORMAL
- en: '`catch`節と`finally`節は、両方またはどちらか片方を記述する'
  prefs:
  - PREF_UL
  type: TYPE_NORMAL
- en: '`throw`文は例外を投げることができ、`Error`オブジェクトを例外として投げる'
  prefs:
  - PREF_UL
  type: TYPE_NORMAL
- en: '`Error`オブジェクトには、ECMAScript仕様や実行環境で定義されたビルトインエラーがある'
  prefs:
  - PREF_UL
  type: TYPE_NORMAL
- en: '`Error`オブジェクトには、スタックトレースが記録され、デバッグに役立てられる'
  prefs:
  - PREF_UL
  type: TYPE_NORMAL
- en: Error Causeを使うことで、別のエラーのスタックトレースを引き継いだ新しいエラーを作成できる*************
  prefs:
  - PREF_UL
  type: TYPE_NORMAL
